Workbook
Name ___INDEX_SHEET___ASAP_Utilities: #REF!
Name ___INDEX_SHEET___ASAP_Utilities: #REF!
Name ___INDEX_SHEET___ASAP_Utilities: #REF!
Name _ftn1: '29. Addl Info to the FS '!#REF!
Name _ftn2: '29. Addl Info to the FS '!#REF!
Name _ftn3: '29. Addl Info to the FS '!#REF!
Name _ftn4: '29. Addl Info to the FS '!#REF!
Name _ftn5: '29. Addl Info to the FS '!#REF!
Name _ftnref5: '29. Addl Info to the FS '!#REF!
Name Contents: #REF!

Sheet Computation

Sheet Disallowances22-23
A4: SUF GROUP 2022 2023
A5: CURRENT LIABILITIES
A6: Group Summary
A7: 1-Apr-22 to 31-Mar-23 | H7: Disallowance | I7: Expense head | J7: Disallowance of
B8: CURRENT LIABILITIES | H8: FY 2022-2023 | J8: FY 2021-2022 | K8: Expense head | L8: Paid On
B9: SUF GROUP 2022 2023
A10: Particulars | B10: 1-Apr-22 to 31-Mar-23
B11: Opening | C11: Transactions | E11: Closing
B12: Balance | C12: Debit | D12: Credit | E12: Balance
A13: DUTIES & TAXES | B13: 47400.36 | C13: 1406505 | D13: 1838487.4 | E13: 384582 | H13: 20400 | I13: Prof Tax - Salary
A14: PROVISIONS | B14: 425500 | C14: 28512139 | D14: 28997639 | E14: 981000 | H14: 90506 | I14: TDS - Salary | J14: 5400 | K14: Salary | L14: 44664
A15: SUNDRY CREDITORS | B15: 259604 | C15: 42094136 | D15: 41764532 | E15: 70000 | H15: 11366 | I15: TDS - Rent | J15: 17327 | K15: Staff TRng - 223, social service - 17085, comp - 19 | L15: 09-04-2022, 13-04-2022
A16: ESI PAYABLE | B16: 57147 | C16: 930496.99 | D16: 1030232 | E16: 156882 | H16: 37880 | I16: TDS- Contractors | J16: 80826 | K16: audit fees - 2500, mohan vs advance - 5k, prof chgs - 2400, fin consul - 10300 | L16: 09-04-2022, 13-04-2022
A17: ESI CO CONTRIBUTION PAYABLE | B17: 46403 | C17: 755635.99 | D17: 836633.99 | E17: 127401 | G17: =SUM(H13:H17) -> 384582 | H17: 224430 | I17: TDS - Professional | J17: 12745 | K17: Rent | L17: 44660
A18: ESI EMPLOYEE CONTRIBUTION PAYABLE | B18: 10744 | C18: 174861 | D18: 193598 | E18: 29481 | G18: =E16 -> 156882 | I18: Salary | J18: 7405 | K18: Salary | L18: 44660
A19: GRANT UNNATI - UNUTILISED | B19: 9296220 | C19: 85266289 | D19: 176340817 | E19: 100370748 | J19: 234000 | K19: Youth training exps (vision fly ) - Op bal 3,96,000 , out of which 234000 is written back | L19: Unpaid / written back
A20: PROVIDENT FUNDS PAYABLE | B20: 262442 | C20: 4862577 | D20: 5405965 | E20: 805830 | G20: =E20 -> 805830 | I20: Salary | J20: 1104 | K20: Comp - grant (tata power extra bill) | L20: Unpaid / written back
A21: REFUNDABLE DEPOSIT | B21: 186900 | C21: 186900 | H21: 95000 | I21: Audit fees | J21: 3500 | K21: FA | L21: 44687
A22: Grand Total | B22: 10440413 | C22: 1.6325904e+08 | D22: 2.5537767e+08 | E22: 102559042 | G22: =H21+H22 -> 819000 | H22: 724000 | I22: Youth training exps only of FY 2022-2023, minus op bal disallowed in FY 2021-2022 | J22: -50000 | K22: Advance to creditors added to application, to be reduced from application of FY 2022-2023 | L22: 44639
G23: 50000 | H23: Advance to creditors added to application in FY 2021-2022, to be reduced from application of FY 2022-2023 | J23: 30000 | K23: Rent | L23: Unpaid / written back
G24: -70000 | H24: Advance to creditors added to application for FY 2022-2023, to be reduced from application of FY 2023-2024 | J24: 135000 | K24: Youth Trng Exps | L24: 44664
J25: 46403 | K25: Salary | L25: 44664
J26: 10744 | K26: Salary | L26: 44664
J27: 148693 | K27: Salary | L27: 06-04-2022, 13-04-2022
J28: 113749 | K28: Salary
H30: =SUM(H13:H29) -> 1203582 | J30: =SUM(J13:J29) -> 796896

Sheet Balance Sheet
A1: SOCIAL FOUNDATION
A2: CIN:
A3: Address:
A4: Balance Sheet as at 31st March, 2025
A7: Particulars | E7: Note No. | F7: As at 31 March, 2025 | G7: As at 31 March, 2024
F8: INR | G8: INR
A9: A | B9: EQUITY AND LIABILITIES
A11: 1 | B11: Shareholders’ funds
B12: (a) Share capital | E12: 1
A14: 2 | B14: Reserves and Earmarked Funds | E14: 2
A16: 3 | B16: Non-current liabilities
A18: 4 | B18: Current liabilities | E18: 3
D20: TOTAL | F20: =SUM(F12:F19) -> 0 | G20: =SUM(G12:G19) -> 0
A22: B | B22: ASSETS
A24: 1 | B24: Fixed Assets | E24: 13&13A
A26: 2 | B26: Non-current assets | E26: 4
A28: 3 | B28: Current assets | E28: 5
D30: TOTAL | F30: =SUM(F24:F29) -> 0 | G30: =SUM(G24:G29) -> 0
B31: See accompanying notes forming part of the financial statements | F31: =F20-F30 -> 0
A32: As per our report of even date:
A33: For Auditor | E33: For and on behalf of the Board of Directors
A34: Chartered Accountants | E34: Social Foundation
A35: ICAI FR No:
A40: Partner | E40: Director | G40: Director
A41: ICAI MRN: | E41: DIN: | G41: DIN:
A42: UDIN:
A43: Place :
A44: Date :

Sheet Income & Expenditure
A1: SOCIAL FOUNDATION
A2: CIN:
A3: Address:
A4: Statement of Income and Expenditure for the year ended 31st March 2025
A6: Particulars | C6: Note No. | D6: For the year ended 31 March, 2025 | E6: For the year ended 31 March, 2024
D7: INR | E7: INR
A8: A | B8: CONTINUING OPERATIONS
A10: 1 | B10: Donations & Grants Received | C10: 6
A11: 2 | B11: Other income | C11: 7
A13: 3 | B13: Total revenue (1+2) | D13: =SUM(D10:D12) -> 0 | E13: =SUM(E10:E12) -> 0
A14: 4 | B14: Expenses
B15: (a) Salaries, Allowances & Benefits | C15: 8
B16: (b) Program Expenses | C16: 9
B17: (c) General & Admin Expenses | C17: 10
B18: ( d ) Depreciation | C18: 13A
B20: Total expenses (4) | D20: =SUM(D15:D19) -> 0 | E20: =SUM(E15:E19) -> 0
A22: 5 | B22: Excess of Income / (Expenditure) before extraordinary items and tax | D22: =+D13-D20 -> 0 | E22: =+E13-E20 -> 0
A23: 6 | B23: Exceptional items | D23: 0 | E23: 0
A24: 7 | B24: Excess of Income / (Expenditure) before extraordinary items and tax (5 + 6) | D24: =+D23+D22 -> 0 | E24: =+E23+E22 -> 0
A25: 8 | B25: Prior Period Adjustments for Depreciation | E25: 0
A26: 9 | B26: Excess of Income / (Expenditure) before tax (7 + 8) | D26: =+D25+D24 -> 0 | E26: =+E25+E24 -> 0
A27: 10 | B27: Tax expense:
B28: Income Tax | D28: 0 | E28: 0
A29: 11 | B29: Excess of Income / (Expenditure) from continuing operations (9 +10) | D29: =+D28+D26 -> 0 | E29: =+E28+E26 -> 0
A30: B | B30: DISCONTINUING OPERATIONS
A31: 12 | B31: Excess of Income / (Expenditure) from discontinuing operations (before tax) | D31: 0 | E31: 0
A32: 13 | B32: Excess of Income / (Expenditure) from discontinuing operations (12.i + 12.ii + 12.iii) | D32: =+D31 -> 0 | E32: =+E31 -> 0
A33: C | B33: TOTAL OPERATIONS
A34: 14 | B34: Excess of Income / (Expenditure) for the year (11 + 13) | D34: =+D29+D32 -> 0 | E34: =+E29+E32 -> 0
A36: 15.i | B36: Earnings per share (of RS. 10/- each):
B37: (a) Basic
B38: (i) Continuing operations | D38: =+D29/10000 -> 0 | E38: =+E29/10000 -> 0
B39: (ii) Total operations | D39: =+D34/10000 -> 0 | E39: =+E34/10000 -> 0
B40: (b) Diluted
B41: (i) Continuing operations | D41: =+D38 -> 0 | E41: =+E38 -> 0
B42: (ii) Total operations | D42: =+D39 -> 0 | E42: =+E39 -> 0
A43: 15.ii | B43: Earnings per share (excluding extraordinary items) (of Rs. 10/- each):
B44: (a) Basic
B45: (i) Continuing operations | D45: =+D38 -> 0 | E45: =+E38 -> 0
B46: (ii) Total operations | D46: =+D39 -> 0 | E46: =+E39 -> 0
...

Sheet Fund Based I&E
A1: SOCIAL FOUNDATION
A2: CIN:
A3: Address:
A4: Fund Based Statement of Income and Expenditure for the year ended 31st March 2025
A7: Particulars | B7: For the year ended 31st March, 2025 (INR)
B8: Restricted Funds | C8: Unrestricted Funds | D8: Total
A9: Income
A10: Donations & Grants | D10: ='Income & Expenditure'!D10 -> 0
A11: Other Income | B11: 0 | C11: =+D11 -> 0 | D11: ='Income & Expenditure'!D11 -> 0
A12: Total Income | B12: =SUM(B10:B11) -> 0 | C12: =SUM(C10:C11) -> 0 | D12: =SUM(D10:D11) -> 0
A14: Expenditure | E14: Adobe | F14: Broadridge | G14: Cardinal Health | H14: Compass India Support Services Pvt Ltd | I14: Deloitte Foundation | J14: E2E Rail | K14: Essel Social Welfare Foundation | L14: Exxon Mobil | M14: Finastra | N14: GE BE Pvt Ltd | O14: GE India Industrial Pvt Ltd | P14: Infosys Foundation | Q14: Intertrust Videos India | R14: Intek Tapes | S14: Microchip Tech (I) Pvt Ltd | T14: MUFG Bank Ltd | U14: NASDAQ | V14: Nextwealth | W14: Omega Healthcare Management Services | X14: Rubrik | Y14: Societe Generale Global Solutions Centre Pvt Ltd | Z14: SSE-ZCZP | AA14: Tata Capital Financial Services Ltd | AB14: Tata Hitachi | AC14: Tata Power Community Development Trust | AD14: Tata Power Delhi Distribution Ltd | AE14: The Boeing Company Ltd | AF14: Unisys India Pvt Ltd | AG14: Total
A15: Salaries, Allowances & Benefits | E15: 1158654 | F15: 6205000 | G15: 20093 | H15: 2215437 | I15: 2564023 | K15: 1045491 | L15: 11287238 | M15: 1092220 | N15: 137783 | O15: 3342149 | P15: 71874192 | Q15: 405549 | R15: 269280 | S15: 1455918 | T15: 7585265 | U15: 157877 | V15: 1315168 | W15: 4085278 | X15: 994258 | Y15: 3636654 | Z15: =12293451+185806+548295+513468.88 -> 13541021 | AB15: 400000 | AC15: 458251 | AD15: 2100000 | AE15: 3194354 | AF15: =260476+323200 -> 583676 | AG15: =SUM(E15:AF15) -> 1.4112483e+08
A16: Program Expenses
A17: Asset Purchases From Restricted Funds | AE17: 1032818 | AG17: =SUM(E17:AF17) -> 1032818
A18: Bank Charges | K18: 125 | Z18: 50000 | AG18: =SUM(E18:AF18) -> 50125
A19: Catering & Pantry Expenses | K19: 9670 | W19: 49773 | Y19: 2092750 | AF19: 163947 | AG19: =SUM(E19:AF19) -> 2316140
A20: Centre Setup & Shifting Expenses | W20: 109210 | AE20: 630323.2 | AG20: =SUM(E20:AF20) -> 739533.2
A21: Computer Maintenance | K21: 475 | W21: 29536 | Z21: =402+9305 -> 9707 | AG21: =SUM(E21:AF21) -> 39718
A22: Electricity & Water | W22: 106768 | AF22: 16373 | AG22: =SUM(E22:AF22) -> 123141
A23: Housekeeping, Repairs & Maintenance | K23: 44878 | W23: =39099+2374 -> 41473 | AD23: 50000 | AE23: 748334.94 | AG23: =SUM(E23:AF23) -> 884685.94
A24: Interest on Unutilised Grants | AG24: =SUM(E24:AF24) -> 0
A25: Medical Expenses | AG25: =SUM(E25:AF25) -> 0
A26: Membership Fees | T26: 309400 | AG26: =SUM(E26:AF26) -> 309400
A27: Miscelleneous Expenses | AG27: =SUM(E27:AF27) -> 0
A28: Monitoring & Supervision Cost | AG28: =SUM(E28:AF28) -> 0
A29: Outreach Expenses | K29: 212350 | O29: 1050000 | P29: 982172 | Q29: 335984 | T29: 77232 | U29: 333719 | W29: 336287 | Y29: 499994 | Z29: =175008.56+1673 -> 176681.56 | AC29: 76186 | AF29: 14408 | AG29: =SUM(E29:AF29) -> 4095013.6
A30: Postage, Telephone & Internet Expenses | K30: 15395 | P30: 27315 | W30: 58534 | Z30: =4867.36 -> 4867.36 | AG30: =SUM(E30:AF30) -> 106111.36
A31: Printing and stationery | K31: 8527 | AG31: =SUM(E31:AF31) -> 8527
A32: Rent | G32: 1070 | I32: 40647 | N32: 7335 | O32: 4431 | P32: 1549959 | Q32: 6724 | T32: 1178630.1 | U32: 8404 | W32: =916920+230429 -> 1147349 | Y32: 61123 | Z32: 276179.77 | AE32: 22921 | AF32: 136000 | AG32: =SUM(E32:AF32) -> 4440772.9
A33: Software Subscription | P33: 327541 | W33: 18522 | Z33: 58362.92 | AE33: 397382.6 | AG33: =SUM(E33:AF33) -> 801808.52
A34: Staff Training, Recruitment & HR Expenses | E34: 360150 | G34: 38837 | I34: 295689 | K34: 41284 | M34: 339500 | O34: 668850 | P34: =12871467+2263469 -> 15134936 | Q34: 40448 | S34: 452550 | V34: 408800 | W34: =4022+404529 -> 408551 | X34: 309050 | Y34: 666275.62 | Z34: =2293505.38+403316.72 -> 2696822.1 | AE34: 292709.26 | AG34: =SUM(E34:AF34) -> 22154452
A35: Training Materials & Other Expenses | P35: 177541 | W35: 65584 | Z35: 22330.29 | AF35: 6354 | AG35: =SUM(E35:AF35) -> 271809.29
A36: Training Partner Expenses | I36: 2099641 | N36: 296882 | O36: 841088 | Q36: 11295 | R36: 230720 | T36: 7880739 | W36: 708921 | AF36: 1050000 | AG36: =SUM(E36:AF36) -> 13119286
A37: Training Software | H37: 148313 | K37: 5387 | P37: 3768706 | W37: 24610 | Y37: 107224.38 | Z37: 671527.71 | AF37: 2998 | AG37: =SUM(E37:AF37) -> 4728766.1
A38: Travelling and conveyance | K38: =200+327000 -> 327200 | P38: 1908860 | Z38: =340130.7+16297-0.29 -> 356427.41 | AF38: 7782 | AG38: =SUM(E38:AF38) -> 2600269.4
A39: HO Cost Allocation | E39: 70138 | J39: 34728.5 | K39: 22185 | L39: 430333 | M39: 68280 | O39: 193482 | P39: 3077105 | S39: 91532 | V39: 76032 | X39: 56692 | Y39: 135979 | AA39: 75000 | AF39: 18462 | AG39: =SUM(E39:AF39) -> 4349948.5
A40: Social Service Project Expenses | J40: 620271.5 | L40: 5252429 | AA40: 1500000 | AG40: =SUM(E40:AF40) -> 7372700.5
A41: General Expenses | AG41: =SUM(E41:AF41) -> 0
A42: Remuneration to Auditors: | AG42: =SUM(E42:AF42) -> 0
A43: (i) Audit Fees | AG43: =SUM(E43:AF43) -> 0
...

Sheet Note 1 Share Capital
A1: SOCIAL FOUNDATION
A2: Notes forming part of the financial statements
A4: Note 1 Share Capital
A6: Particulars | B6: As at 31 March, 2025 | D6: As at 31 March, 2024
B7: Number of shares | C7: INR | D7: Number of shares | E7: INR
A8: (a) Authorised
A9: Equity shares of INR. 10 each with voting rights
A11: (b) Issued
A12: Equity shares of INR. 10 each with voting rights
A14: (c) Subscribed and fully paid up
A15: Equity shares of INR. 10 each with voting rights
A18: Total | B18: =+B15 -> 0 | C18: =+C15 -> 0 | D18: =+D15 -> 0 | E18: =+E15 -> 0
A20: Notes:
A21: (i) Reconciliation of the number of shares and amount outstanding at the beginning and at the end of the reporting period:
A22: Particulars | B22: Opening Balance | C22: Fresh issue | D22: Closing Balance
A23: Equity shares Subscibed & Fully paid up with voting rights
A25: Year ended 31 March, 2025
A26: - Number of shares
A27: - Amount (INR.)
A29: Year ended 31 March, 2024
A30: - Number of shares
A31: - Amount (INR.)
A33: (ii) Details of shares held by each shareholder holding more than 5% shares:
A34: Class of shares / Name of shareholder | B34: As at 31 March, 2025 | D34: As at 31 March, 2024
B35: Number of shares held | C35: % holding in that class of shares | D35: Number of shares held | E35: % holding in that class of shares
A36: Equity shares with voting rights

Sheet Notes 2 to 11
A1: SOCIAL FOUNDATION
A2: Notes forming part of the financial statements
A4: Particulars | B4: As at 31 March, 2025 | C4: As at 31 March, 2024
B5: INR | C5: INR
A7: Note 2 Reserves and surplus
A8: ( a ) Surplus / (Deficit) in Statement of Income & Expenditure
A9: Opening balance
A10: Add: Surplus / (Deficit) for the year
A11: Closing General Fund Balance | B11: =SUM(B9:B10) -> 0 | C11: =SUM(C9:C10) -> 0
A13: (b) Corpus Fund
A14: Opening Balance
A15: Add: Additions during the year
A16: Less: Withdrawn during the year
A17: Closing Corpus Fund Balance | B17: =B14+B15-B16 -> 0 | C17: =C14+C15-C16 -> 0
A19: ( c ) Deffered Grant for Fixed Assets
A21: Total Reserves and Surplus | B21: =B11+B17+B19 -> 0 | C21: =C11+C17+C19 -> 0
A24: Note 3 Current liabilities
A25: (j) Other payables
A26: (i) Audit Fee & other expenses
A27: (ii) Refundable Deposits
A28: (ii) Restricted Fund Balance (Note 12)
A29: (iii) Statutory remittances (Contributions to PF and ESIC, Withholding Taxes, GST etc.)
A30: (iv) Sundry Creditors, Provisions & Other Payables
A32: Total Current Liabilities | B32: =SUM(B26:B31) -> 0 | C32: =SUM(C26:C31) -> 0
A35: Note 4 Non-Current Assets
A36: (a) Fixed Deposits (Scheduled Banks) with maturity > 1 year
A38: Total Non Current Assets | B38: =SUM(B36) -> 0 | C38: =SUM(C36) -> 0
A52: Note 5 Current Assets
A53: (A) Cash and cash equivalents
A54: (a) Cash on hand | B54: =#REF! -> #REF! | C54: 0
A55: (b) Savings accounts (Scheduled Banks) | B55: =SUM(#REF!)-SUM(#REF!) -> #REF! | C55: 20887598
A56: (c) Fixed Deposits (Scheduled Banks) with maturity < 3 months | B56: =#REF!+#REF!-#REF!-#REF!+#REF!+#REF!-#REF!-#REF!-B63-B36 -> #REF! | C56: 81988332
A57: Total (A) | B57: =SUM(B54:B56) -> #REF! | C57: =SUM(C54:C56) -> 1.0287593e+08
A58: (B) Short-term loans and advances, Deposits etc
A59: (a) Balances with government authorities
A60: (i) TDS receivable, Input taxes etc | B60: =SUM(#REF!)-SUM(#REF!) -> #REF! | C60: 1875030.6
A61: (b) Balances with others
A62: (i) Advance to creditors | B62: =#REF!-#REF! -> #REF! | C62: 55000
A63: (ii) Fixed Deposits (Scheduled Banks) with maturity > 3 months and < 12 months | B63: =#REF! -> #REF! | C63: 143915514
A64: (iii) Rent Deposits | B64: =#REF!-#REF! -> #REF! | C64: 478000
...

Sheet Note 12 Restricted Fund Movmnt
A1: SGBS UNNATI FOUNDATION
A2: Notes forming part of the financial statements
A4: Note 12: Restricted Fund Movement for the year and balance as on 31st March 2025
A6: Particulars | B6: Balance as on 01.04.2024 | C6: Funds Recd during FY 2024 2025 | D6: Total Funds for FY 2024-2025 | E6: Utilised for Expenses | F6: Utilised for Asset Purchases | G6: Utilisation for Expenses/Purchase of assets for FY 2024 2025 | H6: Balance as on 31.03.2025
B7: INR | C7: INR | D7: INR | E7: INR | F7: INR | G7: INR | H7: INR
A8: ABC Company | I8: c/fd
A9: XYZ Trust | I9: c/fd
A10: PQR Ltd
A13: Total | B13: =SUM(B8:B12) -> 0 | C13: =SUM(C8:C12) -> 0 | D13: =SUM(D8:D12) -> 0 | E13: =SUM(E8:E12) -> 0 | F13: =SUM(F8:F12) -> 0 | G13: =SUM(G8:G12) -> 0 | H13: =SUM(H8:H12) -> 0
A14: Atlas balances | B14: ='Notes 2 to 11'!C28 -> 0 | G14: =#REF! -> #REF! | H14: =#REF! -> #REF!
A15: Differences | B15: =B13-B14 -> 0 | G15: =G13-G14 -> #REF! | H15: =H13-H14 -> #REF!

Sheet Note 13 & 13A Fixed Assets
A1: SOCIAL FOUNDATION
A2: Notes forming part of the financial statements
A5: Note 13 | B5: FIXED ASSETS: GRANT FUNDS 2024 2025
A6: SN | B6: Description | C6: Op. Bal | D6: Additions | E6: Deletions | F6: Cl. Bal | G6: Depreciation | L6: WDV | M6: WDV
C7: 01.04.2024 | F7: 31.03.2025 | G7: Op Bal 01.04.2024 | H7: FY 2024 2025 | I7: Depreciation on deletions reversed | J7: Total Depreciation for the year | K7: Cl. Bal 31.03.2025 | L7: 31.03.2025 | M7: 31.03.2024
C8: INR | D8: INR | E8: INR | F8: INR | G8: INR | H8: INR | I8: INR | J8: INR | K8: INR | L8: INR | M8: INR
A9: 1 | B9: Computers | L9: =F9-K9 -> 0 | M9: =C9-G9 -> 0
A10: 2 | B10: Furniture & Fixtures | L10: =F10-K10 -> 0 | M10: =C10-G10 -> 0
A11: 3 | B11: Office Equipment | L11: =F11-K11 -> 0 | M11: =C11-G11 -> 0
B13: Grand Total | C13: =SUM(C8:C12) -> 0 | D13: =SUM(D8:D12) -> 0 | E13: =SUM(E8:E12) -> 0 | F13: =SUM(F8:F12) -> 0 | G13: =SUM(G8:G12) -> 0 | H13: =SUM(H8:H12) -> 0 | I13: =SUM(I8:I12) -> 0 | J13: =SUM(J8:J12) -> 0 | ... M13: =SUM(M8:M12) -> 0 | O13: FY | P13: depn | Q13: depn revd | R13: def grant | S13: def grant revd | T13: gen fund revd | U13: def grnt diff | V13: depn diff
B14: Atlas bal | D14: ='Notes 2 to 11'!B100 -> #REF! | F14: =#REF!-#REF! -> #REF! | K14: =#REF!-#REF! -> #REF! | L14: =#REF!-#REF! -> #REF! | N14: grant | O14: 2014-15 | P14: =106446+19527+16551 -> 142524 | Q14: =817186 -> 817186 | R14: 142524 | T14: 817186 | U14: =R14-S14 -> 142524 | V14: =P14-Q14 -> -674662 | W14: =V14+V17 -> -1254086
B15: Difference from Atlas | D15: =D13-D14 -> #REF! | F15: =F13-F14 -> #REF! | K15: =K13-K14 -> #REF! | L15: =L13-L14 -> #REF!
B16: Deferred grant as per B/S | L16: ='Notes 2 to 11'!B19 -> 0
B17: Difference from B/S | L17: =L13-L16 -> 0 | N17: grant | O17: 2015-16 | P17: =1616294+1456030+203869+341705 -> 3617898 | Q17: =4104650+92672 -> 4197322 | R17: =2001604+1616294 -> 3617898 | S17: =4104650+92672 -> 4197322 | U17: =R17-S17 -> -579424 | V17: =P17-Q17 -> -579424
A20: Note 13A | B20: FIXED ASSETS: SELF FUNDED 2024 2025 | N20: grant | O20: 2016-17 | P20: =1126629+709094+189930+429013 -> 2454666 | R20: =1328037+1126629 -> 2454666 | U20: =R20-S20 -> 2454666 | V20: =P20-Q20 -> 2454666
A21: SN | B21: Description | C21: Op. Bal | D21: Additions | E21: Deletions | F21: Cl. Bal | G21: Depreciation | L21: WDV | M21: WDV | N21: suf | O21: 2014-15 | P21: =834171 -> 834171 | Q21: 1755842 | U21: =R21-S21 -> 0 | V21: =P21-Q21 -> -921671 | W21: =V21+V22 -> -716186
C22: 01.04.2024 | F22: 31.03.2025 | G22: Op Bal 01.04.2024 | H22: FY 2024 2025 | I22: Depreciation on deletions reversed | J22: Total Depreciation for the year | K22: Cl. Bal 31.03.2025 | L22: 31.03.2025 | M22: 31.03.2024 | N22: suf | O22: 2015-16 | P22: =1333321 -> 1333321 | Q22: 1127836 | U22: =R22-S22 -> 0 | V22: =P22-Q22 -> 205485
C23: INR | D23: INR | E23: INR | F23: INR | G23: INR | H23: INR | I23: INR | J23: INR | K23: INR | L23: INR | M23: INR | N23: suf | O23: 2016-17 | P23: =23655+1070819 -> 1094474 | U23: =R23-S23 -> 0 | V23: =P23-Q23 -> 1094474
A24: 1 | B24: Computers | L24: =F24-K24 -> 0 | M24: =C24-G24 -> 0 | O24: total | P24: =SUM(P14:P23) -> 9477054 | Q24: =SUM(Q14:Q23) -> 7898186 | R24: =SUM(R14:R23) -> 6215088 | S24: =SUM(S14:S23) -> 4197322 | T24: =SUM(T14:T23) -> 817186 | U24: =R24-S24 -> 2017766 | V24: =P24-Q24 -> 1578868
A25: 2 | B25: Furniture & Fixtures | L25: =F25-K25 -> 0 | M25: =C25-G25 -> 0 | O25: Depn a/c bal | P25: =P24+S24-Q24-R24 -> -438898 | V25: =U24-V24 -> 438898
A26: 3 | B26: Land | L26: =F26-K26 -> 0 | M26: =C26-G26 -> 0
A27: 4 | B27: Office Equipment | L27: =F27-K27 -> 0 | M27: =C27-G27 -> 0
L28: =F28-K28 -> 0 | M28: =C28-G28 -> 0
B29: Grand Total | C29: =SUM(C23:C28) -> 0 | D29: =SUM(D23:D28) -> 0 | E29: =SUM(E23:E28) -> 0 | F29: =SUM(F23:F28) -> 0 | G29: =SUM(G23:G28) -> 0 | H29: =SUM(H23:H28) -> 0 | I29: =SUM(I24:I28) -> 0 | J29: =SUM(J24:J28) -> 0 | K29: =SUM(K23:K28) -> 0 | L29: =SUM(L23:L28) -> 0 | M29: =SUM(M23:M28) -> 0
B30: Atlas bal | F30: =#REF! -> #REF! | K30: =#REF!-#REF! -> #REF! | L30: =#REF!-#REF! -> #REF!
B31: Difference from Atlas | F31: =F29-F30 -> #REF! | K31: =K29-K30 -> #REF! | L31: =L29-L30 -> #REF!
B32: Total WDV | L32: =L29+L13 -> 0
B33: Total as per Trial Balance | L33: =SUM(#REF!)-SUM(#REF!) -> #REF!
B34: Difference fom B/S | L34: =L32-L33 -> #REF!

Sheet Cash Flow
A1: SOCIAL FOUNDATION
A2: CIN:
A3: Address:
A4: Cash Flow Statement for the year ended 31st March, 2025
A7: Particulars | C7: For the year ended 31st March, 2025 | E7: For the year ended 31st March, 2024
C8: INR | D8: INR | E8: INR | F8: INR
A9: A. Cash flow from operating activities
A10: Excess of Income / (Expenditure) before extraordinary items and tax
B11: Adjustment for depreciation
A12: Excess of Income / (Expenditure) before working capital changes
A13: Changes in working capital:
A14: Adjustments for (increase) / decrease in operating assets:
A15: Short-term loans and advances, fixed deposits
A16: Receivables
A17: Non Current Assets
A18: Adjustments for increase / (decrease) in operating liabilities:
A19: Current liabilities
A22: Cash flow from extraordinary items / prior period adjustments
A23: Cash generated from operations
A24: Net income tax (paid) / refunds
A26: Net cash flow from / (used in) operating activities (A)
... A42: Cash and cash equivalents at the end of the year
D43: =D42-'Notes 2 to 11'!B57 -> #REF!
A44: See accompanying notes forming part of the financial statements
A45: As per our report of even date:
A46: For Auditor | C46: For and on behalf of the Board of Directors
A47: Chartered Accountants | C47: Social Foundation
A48: ICAI FR No:
A52: ='Balance Sheet'!A39 -> 0
A53: Partner | C53: Director | E53: Director
A54: ='Balance Sheet'!A41 -> ICAI MRN: | C54: DIN: | E54: DIN:
A55: ='Balance Sheet'!A42 -> UDIN:
A56: Place :
A57: ='Balance Sheet'!A44 -> Date :

Sheet Receipts & Payments
A1: SOCIAL FOUNDATION
A2: CIN:
A3: Address:
A5: RECEIPT AND PAYMENT ACCOUNT FOR THE YEAR ENDED 31.03.2025
G6: AMOUNT (Rs.)
A8: Opening Balances:
B9: Bank - 1 - Local
B10: Bank 2 - FCRA
A13: RECEIPTS:
A14: Donations & Grants
A15: Other Income
A16: Deposits Received
F17: Total | H17: =SUM(H11:H16) -> 0
A18: PAYMENTS:
A19: Program Expenses
A20: General & Admin Expenses
A21: Fixed Asset Purchases
A22: Advances & Deposits given
A25: Closing Balances:
B26: Bank - 1 - Local
B27: Bank 2 - FCRA
F28: Total | H28: 0 | I28: =H17-H28 -> 0
A30: As per our report of even date.
A31: for Auditor
A32: Chartered Accountants | F32: For and on behalf of the Board of Directors
A33: FRNo. | F33: Social Foundation
A36: ='Balance Sheet'!A39 -> 0
A37: Partner
A38: ='Balance Sheet'!A41 -> ICAI MRN: | F38: Director | G38: Director
A39: ='Balance Sheet'!A42 -> UDIN: | F39: DIN: | G39: DIN:
A40: Place:
A41: ='Balance Sheet'!A44 -> Date :

Sheet 26. Finance Costs
B2: Name of the Company
B3: Notes forming part of the financial statements
A5: GN 9.5.5 | B5: Note 26 Finance costs
A7: Ref. No. | B7: Particulars | C7: For the year ended 31 March, 20X2 | D7: For the year ended 31 March, 20X1
C8: ` | D8: `
A9: PL 3 (a) PL 5.i.(e) GN 9.5.5 A | B9: (a) Interest expense on:
B10: (i) Borrowings
B11: (ii) Trade payables
B12: (iii) Others
A13: GN 9.8.1.3 | B13: - Interest on delayed / deferred payment of income tax
B14: - Others (give details)
A16: PL 3 (b) GN 9.5.5 B | B16: (b) Other borrowing costs @
A18: PL 3 (c) GN 9.5.5 C AS 16.4.e | B18: (c) Net (gain) / loss on foreign currency transactions and translation (considered as finance cost)
B20: Total
A21: i | B21: @ Other borrowing costs would include commitment charges, loan processing charges, guarantee charges, loan facilitation charges, discounts / premiums on borrowings, other ancillary costs incurred in connection with borrowings or amortisation of such costs, etc.

Sheet 27. Other Expenses
B2: Name of the Company
B3: Notes forming part of the financial statements
A5: GN 9.5.7 | B5: Note 27 Other expenses
A7: Ref. No. | B7: Particulars | C7: For the year ended 31 March, 20X2 | D7: For the year ended 31 March, 20X1
C8: ` | D8: `
B9: Travelling and conveyance * | C9: =+#REF! -> #REF! | D9: 0
B10: Printing and stationery* | C10: =+#REF! -> #REF! | D10: 0
B11: Legal and professional * | C11: =+#REF! -> #REF! | D11: 0
B12: Charity ( Educational Assistance) | C12: =+#REF! -> #REF! | D12: 0
B13: Audit Fee | C13: 5000 | D13: 0
B14: Bank Charges | C14: =+#REF! -> #REF! | D14: 0
B15: Total | C15: =SUM(C9:C14) -> #REF! | D15: =SUM(D9:D14) -> 0
A16: GN 9.5.7 | B16: Note 27 Other expenses (contd.)
A18: Ref. No. | B18: Particulars
A19: i | B19: @ Consumption of packing materials which are not classified by the Company as part of raw materials should be disclosed separately under Other expenses.
A20: i | B20: # In case of net credit the amount should be included under Other operating revenue in Note 22 Revenue from operations or under Other income in Note 23, as applicable.
A21: i | B21: If an impairment loss is recognised or reversed by the Company, then additional disclosures as required under AS 28 Impairment of Assets needs to be given.
A22: i | B22: Wealth tax and penalties levied under Income Tax laws should not be classified as current tax and should be disclosed under Note 27 Other expenses as part of Rates and taxes.
A23: i | B23: Certain donations need to be disclosed as required under Section 293A / 293B of the Companies Act, 1956.
B24: Notes:
B25: Particulars | C25: For the year ended 31 March, 20X2 | D25: For the year ended 31 March, 20X1
C26: ` | D26: `
A27: PL 5(i)(j) GN 10.3 | B27: (i) Payments to the auditors comprises (net of service tax input credit, where applicable):
B28: As auditors - statutory audit
B29: For taxation matters
B30: For company law matters
B31: For management services
B32: For other services
B33: Reimbursement of expenses
B34: Total
A35: i | B35: Payments for - taxation matters would include tax audit fees, certifications under the Income Tax Act, tax advisory services, etc. - company law matters would include certifications (e.g. certificate for buy-back of shares, etc.), company law advisory services, etc. - other services would include limited reviews, group reporting, other attest services and certifications under other laws, etc.
A36: PL 5(i)(l) | B36: (ii) Details of Prior period items (net)
A37: GN 10.4 | B37: Prior period expenses (give details)
B38: Prior period income (give details)
B39: Total
A40: PL5(i)(c) | B40: ? * Any item of expenditure which exceeds 1% of the revenue from operations or ` 100,000/- whichever is higher should be disclosed. Items which do not meet the criteria may be included as part of Miscellaneous expenses.

Sheet 28. Exceptional & Extraordinary
B2: Name of the Company
B3: Notes forming part of the financial statements
A5: GN 9.6 | B5: Note 28.a Exceptional items @
A7: Ref. No. | B7: Particulars | C7: For the year ended 31 March, 20X2 | D7: For the year ended 31 March, 20X1
C8: ` | D8: `
A9: PL 5.i.k
A10: AS 5.12 AS 5.13 AS 5.14 | B10: (Give details)
B13: Total
A14: i | B14: @ Exceptional items are items of income and expenses which are of such size, nature or incidence that their disclosure (giving details) is relevant to explain the performance of the Company.
A16: GN 9.7 | B16: Note 28.b Extraordinary items #
A18: Ref. No. | B18: Particulars | C18: For the year ended 31 March, 20X2 | D18: For the year ended 31 March, 20X1
C19: ` | D19: `
A20: PL 5.i.k
A21: AS 5.4.2 AS 5.8 | B21: (Give details)
A22: AS 12.20 | B22: Government grants that have become refundable
B24: Total
A25: i | B25: # Extraordinary items are income and expenses that arise from events or transactions that are clearly distinct from ordinary activities of the Company and are not expected to recur frequently or regularly.

Sheet 29. Addl Info to the FS 
B2: Name of the Company
B3: Notes forming part of the financial statements
A5: GN 6.13 | B5: Note 29 Additional information to the financial statements
A7: Ref. No. | B7: Note | C7: Particulars
B9: 29.1 | C9: Monies received against share warrants
A10: BS 6.A.h GN 8.1.3 | C10: The Board of Directors of the Company at their meeting held on X July, 20XX and as approved at its Annual General Meeting held on XX July, 20XX have resolved to create, offer, issue and allot up to _____ warrants, convertible into _____ equity shares of ` __/- each on a preferential allotment basis, pursuant to Section 81(1A) of the Companies Act, 1956, at a conversion price of ` ___/- per equity share of the Company, arrived at in accordance with the SEBI Guidelines in this regard and subsequently these warrants were allotted on (date) to the promoters and the 10% application money amounting to ` ______ was received from them. The warrants may be converted into equivalent number of shares on payment of the balance amount at any time on or before 31 July, 20XX. In the event the warrants are not converted into shares within the said period, the Company is eligible to forfeit the amounts received towards the warrants.
B12: 29.2 | C12: Share application money pending allotment
A13: BS 6.A.h GN 8.2 | C13: As at 31 March 20X2, the Company has received an amount of `_____ towards share application money towards ____ equity / preference shares of the Company (As at 31 March, 20X1 ` ____ towards ____ equity/preference shares) at a premium of ` ____ (As at 31 March, 20X1 ` ____). The share application money was received pursuant to an invitation to offer shares and in terms of such invitation, the Company is required to complete the allotment formalities by _____ (As at 31 March, 20X1 ______). The Company has sufficient authorised capital to cover the allotment of these shares. Pending allotment of shares, the amounts are maintained in a designated bank account and is not available for use by the Company.
A14: GN 8.2.3 | C14: ? Give details of the terms and conditions, number of shares proposed to be issued, the amount of premium, if any, the period before which the shares are to be allotted, whether the Company has sufficient authorised capital to allot the shares and the period beyond which the share application money is pending allotment with the reasons therefor, where applicable.
E16: As at 31 March, 20X2 | F16: As at 31 March, 20X1
E17: ` | F17: `
B18: 29.3 | C18: Contingent liabilities and commitments (to the extent not provided for)
A19: BS 6.T.i | B19: (i) | C19: Contingent liabilities
A20: AS 29.68 GN 8.8.7.1 | C20: (a) Claims against the Company not acknowledged as debt (give details)
A21: GN 8.8.7.2 | C21: (b) Guarantees @ (give details)
C22: (c) Other money for which the Company is contingently liable (give details)
A23: AS 29.71 | C23: ? The Company should disclose for each class of contingent liability, the estimated financial effect, the uncertainties relating to any outflow, the possibility of any reimbursement and any asset recognised therefor. If the Company is unable to disclose this information because it is not practicable to do so, that fact should be disclosed.
A24: AS 29.72 | C24: ? In extremely rare cases, disclosures of some or all information relating to contingent liabilities that are required to be presented may prejudice seriously the position of the Company. In such cases, the Company need not disclose the information but should disclose the general nature of the dispute, together with the fact that, the information has not been disclosed and the reason therefor.
E25: As at 31 March, 20X2 | F25: As at 31 March, 20X1
A26: BS 6.T.ii GN 8.8.7.3 | B26: (ii) | C26: Commitments # | E26: ` | F26: `
C27: (a) Estimated amount of contracts remaining to be executed on capital account and not provided for
C28: Tangible assets
A29: AS 26.94.d | C29: Intangible assets
C30: (b) Uncalled liability on shares and other investments partly paid
A31: GN 8.8.7.4 GN 8.8.7.6 | C31: (c) Other commitments (specify nature)
A34: GN 6.13 | B34: Note 29 Additional information to the financial statements (contd.)
A36: Ref. No. | B36: Note | C36: Particulars
A38: i | C38: @ A contingent liability in respect of guarantees arises when the Company issues guarantees to another person on behalf of a third party. However, where the Company undertakes to perform its own obligations, and for this purpose issues, what is called a 'guarantee', it does not represent a contingent liability and it would be misleading to show such items as contingent liabilities in the Balance Sheet. It is also customary for guarantees to be issued by its bankers on behalf of the Company. For this purpose, the Company issues a 'counter-guarantee' to its bankers. Such 'counter-guarantee' is not really a guarantee at all, but is an undertaking to perform what is in any event the obligation of the Company. Hence, such performance guarantees and counter guarantees should not be disclosed as contingent liabilities.
A39: i | C39: # The word ‘commitment’ has not been defined in the Revised Schedule VI. 'Other commitments' would include all expenditure related contractual commitments such as commitments arising from long-term contracts for purchase of raw material, employee contracts, lease commitments, etc. The scope of such terminology is very wide and may include contractual commitments for purchase of inventory, services, investments, sales, employee contracts, etc. However, to give disclosure of all contractual commitments would be contrary to the overarching principle under General Instructions that “a balance shall be maintained between providing excessive detail that may not assist users of financial statements and not providing important information as a result of too much aggregation.” Accordingly, the disclosures required to be made for ‘other commitments’ should include only those non-cancellable contractual commitments (i.e. cancellation of which will result in a penalty disproportionate to the benefits involved) based on the professional judgment of the Management which are material and relevant in understanding the financial statements of the Company and impact the decision making of the users of financial statements. Examples may include commitments in the nature of buy-back arrangements, commitments to fund subsidiaries and associates, non-disposal of investments in subsidiaries and undertakings, derivative related commitments, etc.
A41: BS 6.V GN 8.8.7.8 | B41: 29.4 | C41: Details of unutilised amounts out of issue of securities made for specific purpose
C42: The Company had issued securities (specify type of security) amounting to ` ____ for purposes of _____. As at 31 March, 20X2, an amount of ` ____ (31 March, 20X1 ` ____) is pending utilisation in future periods / is no longer required for the said purpose consequent to completion of the specified activity. Accordingly, the unutilised amount has been invested in term deposits with banks (specify any other nature) / used in the operations of the Company for acquisition of other assets / investments / to meet its working capital requirements.
A44: GN 6.8 GN 8.4.2 GN 8.4.3 | B44: 29.5 | C44: Disclosures required under Section 22 of the Micro, Small and Medium Enterprises Development Act, 2006
C45: Particulars | E45: As at 31 March, 20X2 | F45: As at 31 March, 20X1
E46: ` | F46: `
C47: (i) Principal amount remaining unpaid to any supplier as at the end of the accounting year
C48: (ii) Interest due thereon remaining unpaid to any supplier as at the end of the accounting year
C49: (iii) The amount of interest paid along with the amounts of the payment made to the supplier beyond the appointed day
C50: (iv) The amount of interest due and payable for the year
C51: (v) The amount of interest accrued and remaining unpaid at the end of the accounting year
C52: (vi) The amount of further interest due and payable even in the succeeding year, until such date when the interest dues as above are actually paid
...

Sheet 30.1 AS 7 Disclosures
B2: Name of the Company
B3: Notes forming part of the financial statements
A5: GN 6.13 | B5: Note 30 Disclosures under Accounting Standards
A7: Ref. No. | B7: Note | C7: Particulars | D7: For the year ended 31 March, 20X2 | E7: For the year ended 31 March, 20X1
D8: ` | E8: `
A9: AS 7 | B9: 30.1 | C9: Details of contract revenue and costs
A10: AS 7.38.a | C10: Contract revenue recognised during the year
A11: AS 7.39.a | C11: Aggregate of contract costs incurred and recognised profits (less recognised losses) upto the reporting date
A12: AS 7.39.b | C12: Advances received for contracts in progress
A13: AS 7.39.c | C13: Retention money for contracts in progress
A14: AS 7.41.a | C14: Gross amount due from customers for contract work (asset)
A15: AS 7.41.b | C15: Gross amount due to customers for contract work (liability)

Sheet 30.2 AS 12 Disclosures
B2: Name of the Company
B3: Notes forming part of the financial statements
A5: GN 6.13 | B5: Note 30 Disclosures under Accounting Standards (contd.)
A7: Ref. No. | B7: Note | C7: Particulars | D7: For the year ended 31 March, 20X2 | E7: For the year ended 31 March, 20X1
D8: ` | E8: `
A9: AS 12 | B9: 30.2 | C9: Details of government grants
A10: AS 12.23.ii | B10: 30.2.a | C10: Government grants received by the Company during the year towards
C11: - Subsidies (recognised under _____)
C12: - Duty drawback (recognised under Other operating revenues)
C13: - Other incentives (specify nature) (recognised under ____)
B15: 30.2.b | C15: The Company has received certain equipments and facilities free of cost from ____ towards carrying on research and development. These assets are required to be returned on completion of the specified activity.

Sheet 30.3 AS 14 Disclosures
B2: Name of the Company
B3: Notes forming part of the financial statements
A5: GN 6.13 | B5: Note 30 Disclosures under Accounting Standards (contd.)
A7: Ref. No. | B7: Note | C7: Particulars
A9: AS 14 | B9: 30.3 | C9: Details of amalgamations
A11: AS 14.43 | C11: In terms of the Scheme of Arrangement (the Scheme), __________ and __________________, both subsidiaries of the Company (referred to as ‘Transferor Companies’), have been merged with the Company (Transferee Company), upon which the undertaking and the entire business, including all assets and liabilities of the Transferor Companies stand transferred to and vested in the Transferee Company at their fair value as determined by the Board of Directors of the Transferee Company (or alternatively at their book values). ____ and ______ were engaged in the manufacture of _________________ and were predominantly acting as a captive manufacturer for the Company. The Scheme of Arrangement filed by the Company has been approved by the Honourable High Courts of Judicature at Mumbai, Chennai and Bangalore with an appointed date of 1 January, 200X and an effective date of 31 December, 200X (‘the Effective Date’), being the date on which all the requirements under the Companies Act, 1956 have been completed.
C12: Pursuant to the Scheme, the Company allotted ____ equity shares of ` __/- each (__% of shares in the Transferor Company and ___% of shares in the Transferee Company) to the minority shareholders in the Transferor Companies.
A13: AS 14.45 | C13: Details of assets and liabilities acquired on amalgamation and treatment of the difference between the net assets acquired and cost of investment by the Transferee Company in the Transferor Companies together with the shares issued to the minority shareholders:
D14: Year ended 31 March, 20X2
C15: Value of assets and liabilities acquired: | D15: ` | E15: `
C16: Fixed assets | D16: aaa
C17: Net current assets (give details) | D17: bbb
C18: Secured loans | D18: ccc
C19: Unsecured loans | D19: ddd | E19: XXX
C21: Less:
C22: Carrying value of investments in the Transferor Companies | D22: eee
C23: Value of shares of the Company issued to the minority shareholders | D23: hhh | E23: YYY
C25: Difference considered as goodwill / capital reserve | E25: QQQ

Sheet 30.4 AS 15 Disclosures
B2: Name of the Company
B3: Notes forming part of the financial statements
A5: GN 6.13 | B5: Note 30 Disclosures under Accounting Standards (contd.)
A7: Ref. No. | B7: Note | E7: Particulars
A9: AS 15 | B9: 30.4 | C9: Employee benefit plans
A10: AS 15.47 | B10: 30.4.a | C10: Defined contribution plans
C11: The Company makes Provident Fund and Superannuation Fund contributions to defined contribution plans for qualifying employees. Under the Schemes, the Company is required to contribute a specified percentage of the payroll costs to fund the benefits. The Company recognised ` ___________ (Year ended 31 March, 20X1 ` __________) for Provident Fund contributions and ` _____ (Year ended 31 March, 20X1 ` _______) for Superannuation Fund contributions in the Statement of Profit and Loss. The contributions payable to these plans by the Company are at rates specified in the rules of the schemes.
A12: i | C12: In case the company has contributions to foreign defined contribution plans and benefit plans, the details of the same should be disclosed.
A13: AS 15.120.b | B13: 30.4.b | C13: Defined benefit plans
C14: The Company offers the following employee benefit schemes to its employees:
C15: i. Gratuity
C16: ii. Post-employment medical benefits
C17: iii. Other defined benefit plans (specify nature)
C18: The following table sets out the funded status of the defined benefit schemes and the amount recognised in the financial statements:
I19: `
C20: Particulars | D20: Year ended 31 March, 20X2 | G20: Year ended 31 March, 20X1
D21: Gratuity | E21: Post-employment medical benefits | F21: Other defined benefit plans (specify nature) | G21: Gratuity | H21: Post-employment medical benefits | I21: Other defined benefit plans (specify nature)
A22: AS 15.120.g | C22: Components of employer expense
C23: Current service cost
C24: Interest cost
C25: Expected return on plan assets
C26: Curtailment cost / (credit)
C27: Settlement cost / (credit)
C28: Past service cost
C29: Actuarial losses/(gains)
C30: Total expense recognised in the Statement of Profit and Loss
C32: Actual contribution and benefit payments for year
C33: Actual benefit payments
C34: Actual contributions
A36: AS 15.120.f | C36: Net asset / (liability) recognised in the Balance Sheet
A37: AS 15.120.d | C37: Present value of defined benefit obligation
C38: Fair value of plan assets
C39: Funded status [Surplus / (Deficit)]
C40: Unrecognised past service costs
C41: Net asset / (liability) recognised in the Balance Sheet
A42: GN 6.13 | B42: Note 30 Disclosures under Accounting Standards (contd.)
I43: `
A44: Ref. No. | B44: Note | C44: Particulars | D44: Year ended 31 March, 20X2 | G44: Year ended 31 March, 20X1
D45: Gratuity | E45: Post-employment medical benefits | F45: Other defined benefit plans (specify nature) | G45: Gratuity | H45: Post-employment medical benefits | I45: Other defined benefit plans (specify nature)
A47: AS 15.120.c | C47: Change in defined benefit obligations (DBO) during the year
...

Sheet 30.5 AS 16 Disclosures
B2: Name of the Company
B3: Notes forming part of the financial statements
A5: GN 6.13 | B5: Note 30 Disclosures under Accounting Standards (contd.)
A7: Ref. No. | B7: Note | C7: Particulars | D7: For the year ended 31 March, 20X2 | E7: For the year ended 31 March, 20X1
D8: ` | E8: `
A9: AS 16 | B9: 30.5 | C9: Details of borrowing costs capitalised
A10: AS 16.23.b | C10: Borrowing costs capitalised during the year
C11: - as fixed assets / intangible assets / capital work-in-progress
C12: - as inventory

Sheet 30.6 AS 17 Disclosures
B2: Name of the Company
B3: Notes forming part of the financial statements
A5: GN 6.13 | B5: Note 30 Disclosures under Accounting Standards (contd.)
A7: Ref. No. | B7: Note | C7: Particulars
A9: AS 17 | B9: 30.6 | C9: Segment information
A10: AS 17.58 | C10: The Company has identified business segments as its primary segment and geographic segments as its secondary segment. Business segments are primarily ______________ and ___________. Revenues and expenses directly attributable to segments are reported under each reportable segment. Expenses which are not directly identifiable to each reportable segment have been allocated on the basis of associated revenues of the segment and manpower efforts. All other expenses which are not attributable or allocable to segments have been disclosed as unallocable expenses. Assets and liabilities that are directly attributable or allocable to segments are disclosed under each reportable segment. All other assets and liabilities are disclosed as unallocable. Fixed assets that are used interchangeably amongst segments are not allocated to primary and secondary segments. Geographical revenues are allocated based on the location of the customer. Geographic segments of the Company are Americas (including Canada and South American countries), Europe, India and Others.
C11: Particulars | D11: For the year ended 31 March, 20X2
D12: Business segments | G12: Total
D13: A | E13: B | F13: Eliminations
D14: ` | E14: ` | F14: ` | G14: `
A15: AS 17.40.a | C15: Revenue | D15: YYY | E15: YYY | F15: YYY | G15: YYY
D16: (XXX) | E16: (XXX) | F16: (XXX) | G16: (XXX)
A17: AS 17.40.a | C17: Inter-segment revenue | D17: YYY | E17: YYY | F17: YYY | G17: YYY
D18: (XXX) | E18: (XXX) | F18: (XXX) | G18: (XXX)
C19: Total | D19: YYY | E19: YYY | F19: YYY | G19: YYY
D20: (XXX) | E20: (XXX) | F20: (XXX) | G20: (XXX)
A21: AS 17.40.b | C21: Segment result | D21: YYY | E21: YYY | F21: YYY | G21: YYY
D22: (XXX) | E22: (XXX) | F22: (XXX) | G22: (XXX)
A23: AS 17.46 | C23: Unallocable expenses (net) | G23: YYY
G24: (XXX)
C25: Operating income | G25: YYY
G26: (XXX)
C27: Other income (net) | G27: YYY
G28: (XXX)
C29: Profit before taxes | G29: YYY
G30: (XXX)
C31: Tax expense | G31: YYY
G32: (XXX)
C33: Net profit for the year | G33: YYY
G34: (XXX)
A36: GN 6.13 | B36: Note 30 Disclosures under Accounting Standards (contd.)
A38: Ref. No. | B38: Note | C38: Particulars | D38: For the year ended 31 March, 20X2
D39: Business segments | F39: Total
D40: A | E40: B
D41: ` | E41: ` | F41: `
A42: AS 17.40.c | C42: Segment assets | D42: YYY | E42: YYY | F42: YYY
D43: (XXX) | E43: (XXX) | F43: (XXX)
A44: AS 17.46 | C44: Unallocable assets | F44: YYY
F45: (XXX)
C46: Total assets | F46: YYY
...

Sheet 30.7 AS 18 Disclosures
B2: Name of the Company
B3: Notes forming part of the financial statements
A5: GN 6.13 | B5: Note 30 Disclosures under Accounting Standards (contd.)
A7: Ref. No. | B7: Note | C7: Particulars
A9: AS 18 GN 6.15 | B9: 30.7 | C9: Related party transactions
B10: 30.7.a | C10: Details of related parties:
A11: AS 18.21 | C11: Description of relationship | D11: Names of related parties
A12: AS 18.23 | C12: Ultimate Holding Company | D12: AA Ltd.
C13: Holding Company | D13: A Ltd.
C14: Ultimate Holding Company | D14: AA Ltd.
C15: Subsidiaries | D15: B Ltd. and C (P) Ltd.
C16: Fellow Subsidiaries (to be given only if there are transactions) | D16: D Ltd. and Q Ltd.
C17: Associates | D17: X Ltd. and Y Ltd.
C18: Key Management Personnel (KMP) | D18: Mr. Y and Mr. Z
C19: Relatives of KMP | D19: Mrs. Y (wife of Mr. Y), Mr. F (father of Mr. Z)
C20: Company in which KMP / Relatives of KMP can exercise significant influence | D20: D Ltd in which MD(KMP) and his wife hold 50%
C21: Note: Related parties have been identified by the Management.
C22: Details of related party transactions during the year ended 31 March, 20X2 and balances outstanding as at 31 March, 20X2: | L22: `
A23: AS 18.23 | B23: 30.7.b | D23: Ultimate Holding Company | E23: Holding Company | F23: Subsidiaries | G23: Fellow Subsidiaries | H23: Associates | I23: KMP | J23: Relatives of KMP | K23: Entities in which KMP / relatives of KMP have significant influence | L23: Total
A24: AS 18.24 AS 18.26 | C24: ? Party-wise details - aggregation to be done only if the related party is < 10 % of the total amount of that particular type of transaction - e.g. purchases. Also note that in some cases even less than 10% will be required to be disclosed and such importance depends on circumstances of the respective companies.
C25: Purchase of goods | D25: YYY | E25: YYY | F25: YYY | G25: YYY | H25: YYY | I25: YYY | J25: YYY | K25: YYY | L25: YYY
D26: (XXX) | E26: (XXX) | F26: (XXX) | G26: (XXX) | H26: (XXX) | I26: (XXX) | J26: (XXX) | K26: (XXX) | L26: (XXX)
C27: Sale of goods | D27: YYY | E27: YYY | F27: YYY | G27: YYY | H27: YYY | I27: YYY | J27: YYY | K27: YYY | L27: YYY
D28: (XXX) | E28: (XXX) | F28: (XXX) | G28: (XXX) | H28: (XXX) | I28: (XXX) | J28: (XXX) | K28: (XXX) | L28: (XXX)
C29: Purchase of fixed assets | D29: YYY | E29: YYY | F29: YYY | G29: YYY | H29: YYY | I29: YYY | J29: YYY | K29: YYY | L29: YYY
D30: (XXX) | E30: (XXX) | F30: (XXX) | G30: (XXX) | H30: (XXX) | I30: (XXX) | J30: (XXX) | K30: (XXX) | L30: (XXX)
C31: Sale of fixed assets | D31: YYY | E31: YYY | F31: YYY | G31: YYY | H31: YYY | I31: YYY | J31: YYY | K31: YYY | L31: YYY
D32: (XXX) | E32: (XXX) | F32: (XXX) | G32: (XXX) | H32: (XXX) | I32: (XXX) | J32: (XXX) | K32: (XXX) | L32: (XXX)
C33: Rendering of services | D33: YYY | E33: YYY | F33: YYY | G33: YYY | H33: YYY | I33: YYY | J33: YYY | K33: YYY | L33: YYY
D34: (XXX) | E34: (XXX) | F34: (XXX) | G34: (XXX) | H34: (XXX) | I34: (XXX) | J34: (XXX) | K34: (XXX) | L34: (XXX)
C35: Receiving of services | D35: YYY | E35: YYY | F35: YYY | G35: YYY | H35: YYY | I35: YYY | J35: YYY | K35: YYY | L35: YYY
D36: (XXX) | E36: (XXX) | F36: (XXX) | G36: (XXX) | H36: (XXX) | I36: (XXX) | J36: (XXX) | K36: (XXX) | L36: (XXX)
C37: Agency arrangements | D37: YYY | E37: YYY | F37: YYY | G37: YYY | H37: YYY | I37: YYY | J37: YYY | K37: YYY | L37: YYY
D38: (XXX) | E38: (XXX) | F38: (XXX) | G38: (XXX) | H38: (XXX) | I38: (XXX) | J38: (XXX) | K38: (XXX) | L38: (XXX)
C39: Leasing or hire purchase arrangements | D39: YYY | E39: YYY | F39: YYY | G39: YYY | H39: YYY | I39: YYY | J39: YYY | K39: YYY | L39: YYY
D40: (XXX) | E40: (XXX) | F40: (XXX) | G40: (XXX) | H40: (XXX) | I40: (XXX) | J40: (XXX) | K40: (XXX) | L40: (XXX)
C41: Transfer of research and development | D41: YYY | E41: YYY | F41: YYY | G41: YYY | H41: YYY | I41: YYY | J41: YYY | K41: YYY | L41: YYY
D42: (XXX) | E42: (XXX) | F42: (XXX) | G42: (XXX) | H42: (XXX) | I42: (XXX) | J42: (XXX) | K42: (XXX) | L42: (XXX)
C43: License agreements | D43: YYY | E43: YYY | F43: YYY | G43: YYY | H43: YYY | I43: YYY | J43: YYY | K43: YYY | L43: YYY
D44: (XXX) | E44: (XXX) | F44: (XXX) | G44: (XXX) | H44: (XXX) | I44: (XXX) | J44: (XXX) | K44: (XXX) | L44: (XXX)
...

Sheet 30.8 AS 19 Disclosures
B2: Name of the Company
B3: Notes forming part of the financial statements
A5: GN 6.13 | B5: Note 30 Disclosures under Accounting Standards (contd.)
A7: Ref. No. | B7: Note | C7: Particulars | D7: For the year ended 31 March, 20X2 | E7: For the year ended 31 March, 20X1
D8: ` | E8: `
A9: AS 19 GN 8.8.7.5 | B9: 30.8 | C9: Details of leasing arrangements
A10: AS 19.46 | C10: As Lessor
A11: AS 19.46.d | B11: 30.8.a | C11: The Company has entered into operating lease arrangements for certain surplus facilities. The lease is non-cancellable for a period of ____ years from ____ and may be renewed for a further period of ___ years based on mutual agreement of the parties.
A12: AS 19.46.b | C12: Future minimum lease payments
C13: not later than one year
C14: later than one year and not later than five years
C15: later than five years
A17: AS 19.46.c | C17: Contingent rents recognised as income during the year (state basis)
A19: AS 19.46.a | C19: Depreciation recognised on the leased assets
C20: Impairment losses recognised on the leased assets
C21: Impairment losses reversed on the leased assets
A23: AS 19.37.f | B23: 30.8.b | C23: The Company has entered into finance lease arrangements for certain equipments and vehicles.
A24: AS 19.37.a | C24: Future minimum lease payments and reconciliation of gross investment in the lease and present value of minimum lease payments
C25: Future minimum lease payments
C26: not later than one year
C27: later than one year and not later than five years
C28: later than five years
A30: AS 19.37.b | C30: Less: Unearned finance income
A31: AS 19.37.a | C31: Present value of minimum lease payments receivable
C32: not later than one year
C33: later than one year and not later than five years
C34: later than five years
A36: AS 19.37.c | C36: Unguaranteed residual values accruing to the Company as the lessor
A37: AS 19.37.d | C37: Accumulated provision for doubtful minimum lease payments
A38: AS 19.37.e | C38: Contingent rents recognised as income during the year (state basis)
C40: As Lessee
A41: AS 19.22.f | B41: 30.8.c | C41: The Company has entered into finance lease arrangements for certain equipments and vehicles, which provide the Company an option to purchase the assets at the end of the lease period.
A42: AS 19.22.c | C42: Reconciliation of minimum lease payments
C43: Future minimum lease payments
C44: not later than one year
C45: later than one year and not later than five years
C46: later than five years
C48: Less: Unmatured finance charges
C49: Present value of minimum lease payments payable
C50: not later than one year
...

Sheet 30.9 AS 20 Disclosures
B2: Name of the Company
B3: Notes forming part of the financial statements
A5: GN 6.13 | B5: Note 30 Disclosures under Accounting Standards (contd.)
A7: Ref. No. | B7: Note | C7: Particulars | D7: For the year ended 31 March, 20X2 | E7: For the year ended 31 March, 20X1
D8: ` | E8: `
A9: AS 20 | B9: 30.9 | C9: Earnings per share
C10: Basic
B11: 30.9.a | C11: Continuing operations
A12: AS 20.11 | C12: Net profit / (loss) for the year from continuing operations
A13: AS 20.11 | C13: Less: Preference dividend and tax thereon
A14: AS 20.48.ii | C14: Net profit / (loss) for the year from continuing operations attributable to the equity shareholders
A15: AS 20.48.ii | C15: Weighted average number of equity shares
A16: AS 20.48.ii | C16: Par value per share
A17: AS.20.50 | C17: Earnings per share from continuing operations - Basic
B19: 30.9.b | C19: Total operations
A20: AS 20.11 | C20: Net profit / (loss) for the year
A21: AS 20.11 | C21: Less: Preference dividend and tax thereon
A22: AS 20.48.ii | C22: Net profit / (loss) for the year attributable to the equity shareholders
A23: AS 20.48.ii | C23: Weighted average number of equity shares
A24: AS 20.48.ii | C24: Par value per share
C25: Earnings per share - Basic
C27: Basic (excluding extraordinary items)
B28: 30.9.c | C28: Continuing operations
A29: AS 20.11 | C29: Net profit / (loss) for the year from continuing operations
A30: AS 20.48.i | C30: (Add) / Less: Extraordinary items (net of tax) relating to continuing operations
A31: AS 20.11 | C31: Less: Preference dividend and tax thereon
A32: AS 20.48.ii | C32: Net profit / (loss) for the year from continuing operations attributable to the equity shareholders, excluding extraordinary items
A33: AS 20.48.ii | C33: Weighted average number of equity shares
A34: AS 20.48.ii | C34: Par value per share
A35: AS.20.48.i | C35: Earnings per share from continuing operations, excluding extraordinary items - Basic
B37: 30.9.d | C37: Total operations
A38: AS 20.11 | C38: Net profit / (loss) for the year
A39: AS 20.48.i | C39: (Add) / Less: Extraordinary items (net of tax)
A40: AS 20.11 | C40: Less: Preference dividend and tax thereon
A41: AS 20.48.ii | C41: Net profit / (loss) for the year attributable to the equity shareholders, excluding extraordinary items
A42: AS 20.48.ii | C42: Weighted average number of equity shares
A43: AS 20.48.ii | C43: Par value per share
A44: AS.20.48.i | C44: Earnings per share, excluding extraordinary items - Basic
C46: Diluted
C47: The diluted earnings per share has been computed by dividing the Net Profit After Tax available for Equity Shareholders by the weighted average number of equity shares, after giving dilutive effect of the outstanding Warrants, Stock Options and Convertible bonds for the respective periods. Since, the effect of the conversion of Preference shares was anti-dilutive, it has been ignored.
...

Sheet 30.10 AS 22 Disclosures 
B2: Name of the Company
B3: Notes forming part of the financial statements
A5: GN 6.13 | B5: Note 30 Disclosures under Accounting Standards (contd.)
A7: Ref. No. | B7: Note | C7: Particulars | D7: As at 31 March, 20X2 | E7: As at 31 March, 20X1
D8: ` | E8: `
A9: AS 22 GN 7.6 | B9: 30.10 | C9: Deferred tax (liability) / asset
A10: AS 22.31 | C10: Tax effect of items constituting deferred tax liability
C11: On difference between book balance and tax balance of fixed assets
C12: On expenditure deferred in the books but allowable for tax purposes
C13: On items included in Reserves and surplus pending amortisation into the Statement of Profit and Loss
C14: Others
C15: Tax effect of items constituting deferred tax liability
A17: AS 22.31 | C17: Tax effect of items constituting deferred tax assets
C18: Provision for compensated absences, gratuity and other employee benefits
C19: Provision for doubtful debts / advances
C20: Disallowances under Section 40(a)(i), 43B of the Income Tax Act, 1961
C21: On difference between book balance and tax balance of fixed assets
C22: Unabsorbed depreciation carried forward
C23: Brought forward business losses
C24: On items included in Reserves and surplus pending amortisation into the Statement of Profit and Loss
C25: Others
C26: Tax effect of items constituting deferred tax assets
C29: Net deferred tax (liability) / asset
A31: AS 22.32 | C31: The Company has recognised deferred tax asset on unabsorbed depreciation to the extent of the corresponding deferred tax liability on the difference between the book balance and the written down value of fixed assets under Income Tax (or) The Company has recognised deferred tax asset on unabsorbed depreciation and brought forward business losses based on the Management's estimates of future profits considering the non-cancellable customer orders received by the Company.
A32: i | C32: The net deferred tax liability / asset should always be classified as non-current and disclosed on the face of the Balance Sheet.

Sheet 30.11 AS 24 Disclosures 
B2: Name of the Company
B3: Notes forming part of the financial statements
A5: GN 6.13 | B5: Note 30 Disclosures under Accounting Standards (contd.)
A7: Ref. No. | B7: Note | C7: Particulars
A9: AS 24 | B9: 30.11 | C9: Discontinuing operations
A10: AS 24.20 | C10: During the year, pursuant to the approval of the Shareholders and other authorities as required, the Company has transferred the ________ business to _______________ on a slump sale basis with effect from the close of business on _____________ for a consideration of `______________. The ____ business was reported as part of _____ segment of the Company. The results of the discontinued business during the year until discontinuation were as under:
C12: Profit / (Loss) from ordinary activities | D12: For the year ended 31 March, 20X2 | E12: For the year ended 31 March, 20X1
D13: ` | E13: `
C14: Sale of products
C15: Sale of services
C16: Other operating revenue
A17: AS 24.20.f | C17: Total revenue (A)
